Workbook

Sheet Dev_sample
A1: checking_status | B1: duration | C1: credit_history | D1: purpose | E1: credit_amount | F1: savings_status | G1: employment | H1: installment_commitment | I1: personal_status | J1: other_parties | K1: residence_since | L1: property_magnitude | M1: age | N1: other_payment_plans | O1: housing | P1: existing_credits | Q1: job | R1: num_dependents | S1: own_telephone | T1: foreign_worker | U1: class
A2: 0<=X<200 | B2: 54 | C2: no credits/all paid | D2: business | E2: 15945 | F2: <100 | G2: <1 | H2: 3 | I2: male single | J2: none | K2: 4 | L2: no known property | M2: 58 | N2: none | O2: rent | P2: 1 | Q2: skilled | R2: 1 | S2: yes | T2: yes | U2: 1
A3: <0 | B3: 48 | C3: existing paid | D3: business | E3: 4308 | F3: <100 | G3: <1 | H3: 3 | I3: female div/dep/mar | J3: none | K3: 4 | L3: life insurance | M3: 24 | N3: none | O3: rent | P3: 1 | Q3: skilled | R3: 1 | S3: none | T3: yes | U3: 1
A4: 0<=X<200 | B4: 48 | C4: all paid | D4: business | E4: 6416 | F4: <100 | G4: >=7 | H4: 4 | I4: female div/dep/mar | J4: none | K4: 3 | L4: no known property | M4: 59 | N4: none | O4: rent | P4: 1 | Q4: skilled | R4: 1 | S4: none | T4: yes | U4: 1
A5: 0<=X<200 | B5: 48 | C5: all paid | D5: new car | E5: 12169 | F5: no known savings | G5: unemployed | H5: 4 | I5: male single | J5: co applicant | K5: 4 | L5: no known property | M5: 36 | N5: none | O5: for free | P5: 1 | Q5: high qualif/self emp/mgmt | R5: 1 | S5: yes | T5: yes | U5: 0
A6: <0 | B6: 48 | C6: no credits/all paid | D6: furniture/equipment | E6: 7119 | F6: <100 | G6: 1<=X<4 | H6: 3 | I6: male single | J6: none | K6: 4 | L6: no known property | M6: 53 | N6: none | O6: for free | P6: 2 | Q6: skilled | R6: 2 | S6: none | T6: yes | U6: 1
A7: 0<=X<200 | B7: 48 | C7: no credits/all paid | D7: business | E7: 14421 | F7: <100 | G7: 1<=X<4 | H7: 2 | I7: male single | J7: none | K7: 2 | L7: car | M7: 25 | N7: none | O7: own | P7: 1 | Q7: skilled | R7: 1 | S7: yes | T7: yes | U7: 1
A8: <0 | B8: 48 | C8: all paid | D8: business | E8: 7685 | F8: <100 | G8: 4<=X<7 | H8: 2 | I8: female div/dep/mar | J8: guarantor | K8: 4 | L8: car | M8: 37 | N8: none | O8: rent | P8: 1 | Q8: skilled | R8: 1 | S8: none | T8: yes | U8: 1
A9: <0 | B9: 48 | C9: existing paid | D9: new car | E9: 7763 | F9: <100 | G9: >=7 | H9: 4 | I9: male single | J9: none | K9: 4 | L9: no known property | M9: 42 | N9: bank | O9: for free | P9: 1 | Q9: high qualif/self emp/mgmt | R9: 1 | S9: none | T9: yes | U9: 1
A10: 0<=X<200 | B10: 48 | C10: no credits/all paid | D10: other | E10: 18424 | F10: <100 | G10: 1<=X<4 | H10: 1 | I10: female div/dep/mar | J10: none | K10: 2 | L10: life insurance | M10: 32 | N10: bank | O10: own | P10: 1 | Q10: high qualif/self emp/mgmt | R10: 1 | S10: yes | T10: no | U10: 1
A11: <0 | B11: 24 | C11: all paid | D11: new car | E11: 1193 | F11: <100 | G11: unemployed | H11: 1 | I11: female div/dep/mar | J11: co applicant | K11: 4 | L11: no known property | M11: 29 | N11: none | O11: rent | P11: 2 | Q11: unemp/unskilled non res | R11: 1 | S11: none | T11: yes | U11: 1
A12: 0<=X<200 | B12: 48 | C12: no credits/all paid | D12: new car | E12: 8358 | F12: 500<=X<1000 | G12: <1 | H12: 1 | I12: female div/dep/mar | J12: none | K12: 1 | L12: car | M12: 30 | N12: none | O12: own | P12: 2 | Q12: skilled | R12: 1 | S12: none | T12: yes | U12: 0
A13: 0<=X<200 | B13: 36 | C13: all paid | D13: domestic appliance | E13: 3990 | F13: no known savings | G13: <1 | H13: 3 | I13: female div/dep/mar | J13: none | K13: 2 | L13: no known property | M13: 29 | N13: bank | O13: own | P13: 1 | Q13: unemp/unskilled non res | R13: 1 | S13: none | T13: yes | U13: 0
... A701: no checking | B701: 9 | C701: critical/other existing credit | D701: radio/tv | E701: 3074 | F701: no known savings | G701: 1<=X<4 | H701: 1 | I701: male single | J701: none | K701: 2 | L701: real estate | M701: 33 | N701: none | O701: own | P701: 2 | Q701: skilled | R701: 2 | S701: none | T701: yes | U701: 0

Sheet Binning_WOE_IV
A1: Numeric Variables | B1: Bin | C1: Min | D1: Max | E1: Good | F1: Bad | G1: GoodDist | H1: BadDist | I1: WOE | J1: IV_bin | K1: IV_total | L1: evaluation | AF1: credit_history | AG1: credit_history_bin | AH1: purpose | AI1: purpose_bin | AJ1: savings_status | AK1: savings_status_bin | AL1: employment | AM1: employment_bin | AN1: personal_status | AO1: personal_status_bin | AP1: other_parties | AQ1: property_magnitude | AR1: property_magnitude_bin | AS1: other_payment_plans | AT1: other_payment_plans_bin | AU1: housing | AV1: housing_bin | AW1: job | AX1: own_telephone | AY1: foreign_worker | AZ1: checking_status
A2: duration | B2: 1 | C2: 0 | D2: 12 | E2: =COUNTIFS(Dev_sample!B:B,">="&Binning_WOE_IV!C2,Dev_sample!B:B,"<"&Binning_WOE_IV!D2,Dev_sample!U:U,0) -> 112 | F2: =COUNTIFS(Dev_sample!B:B,">="&Binning_WOE_IV!C2,Dev_sample!B:B,"<"&Binning_WOE_IV!D2,Dev_sample!U:U,1) -> 18 | G2: =E2/SUM($E$2:$E$6) -> 0.23092784 | H2: =F2/SUM($F$2:$F$6) -> 0.08372093 | I2: =LN(Binning_WOE_IV!G2/Binning_WOE_IV!H2) -> 1.0146163 | J2: =(Binning_WOE_IV!G2-Binning_WOE_IV!H2)*Binning_WOE_IV!I2 -> 0.14935852 | K2: =SUM(J2:J6) -> 0.27075808 | L2: accept | AF2: critical/other existing credit | AG2: bin1 | AH2: radio/tv | AI2: bin1 | AJ2: no known savings | AK2: bin1 | AL2: >=7 | AM2: bin4 | AN2: male single | AO2: bin1 | AP2: none | AQ2: real estate | AR2: bin1 | AS2: none | AT2: bin1 | AU2: own | AV2: bin1 | AW2: skilled | AX2: yes | AY2: yes | AZ2: <0
A3: duration | B3: 2 | C3: 12 | D3: 24 | E3: =COUNTIFS(Dev_sample!B:B,">="&Binning_WOE_IV!C3,Dev_sample!B:B,"<"&Binning_WOE_IV!D3,Dev_sample!U:U,0) -> 201 | F3: =COUNTIFS(Dev_sample!B:B,">="&Binning_WOE_IV!C3,Dev_sample!B:B,"<"&Binning_WOE_IV!D3,Dev_sample!U:U,1) -> 83 | G3: =E3/SUM($E$2:$E$6) -> 0.41443299 | H3: =F3/SUM($F$2:$F$6) -> 0.38604651 | I3: =LN(Binning_WOE_IV!G3/Binning_WOE_IV!H3) -> 0.070953437 | J3: =(Binning_WOE_IV!G3-Binning_WOE_IV!H3)*Binning_WOE_IV!I3 -> 0.0020141182 | AF3: existing paid | AG3: bin2 | AH3: education | AI3: bin2 | AJ3: <100 | AK3: bin2 | AL3: 1<=X<4 | AM3: bin3 | AN3: female div/dep/mar | AO3: bin2 | AP3: guarantor | AQ3: life insurance | AR3: bin2 | AS3: bank | AT3: bin2 | AU3: for free | AV3: bin2 | AW3: unskilled resident | AX3: none | AY3: no | AZ3: 0<=X<200
A4: duration | B4: 3 | C4: 24 | D4: 36 | E4: =COUNTIFS(Dev_sample!B:B,">="&Binning_WOE_IV!C4,Dev_sample!B:B,"<"&Binning_WOE_IV!D4,Dev_sample!U:U,0) -> 113 | F4: =COUNTIFS(Dev_sample!B:B,">="&Binning_WOE_IV!C4,Dev_sample!B:B,"<"&Binning_WOE_IV!D4,Dev_sample!U:U,1) -> 57 | G4: =E4/SUM($E$2:$E$6) -> 0.23298969 | H4: =F4/SUM($F$2:$F$6) -> 0.26511628 | I4: =LN(Binning_WOE_IV!G4/Binning_WOE_IV!H4) -> -0.12917431 | J4: =(Binning_WOE_IV!G4-Binning_WOE_IV!H4)*Binning_WOE_IV!I4 -> 0.0041499299 | AF4: delayed previously | AG4: bin2 | AH4: furniture/equipment | AI4: bin3 | AJ4: 500<=X<1000 | AK4: bin4 | AL4: 4<=X<7 | AM4: bin4 | AN4: male div/sep | AO4: bin3 | AP4: co applicant | AQ4: no known property | AR4: bin4 | AS4: stores | AT4: bin2 | AU4: rent | AV4: bin2 | AW4: high qualif/self emp/mgmt | AZ4: no checking
A5: duration | B5: 4 | C5: 36 | D5: 48 | E5: =COUNTIFS(Dev_sample!B:B,">="&Binning_WOE_IV!C5,Dev_sample!B:B,"<"&Binning_WOE_IV!D5,Dev_sample!U:U,0) -> 38 | F5: =COUNTIFS(Dev_sample!B:B,">="&Binning_WOE_IV!C5,Dev_sample!B:B,"<"&Binning_WOE_IV!D5,Dev_sample!U:U,1) -> 33 | G5: =E5/SUM($E$2:$E$6) -> 0.078350515 | H5: =F5/SUM($F$2:$F$6) -> 0.15348837 | I5: =LN(Binning_WOE_IV!G5/Binning_WOE_IV!H5) -> -0.67243226 | J5: =(Binning_WOE_IV!G5-Binning_WOE_IV!H5)*Binning_WOE_IV!I5 -> 0.050525119 | AF5: no credits/all paid | AG5: bin3 | AH5: new car | AI5: bin4 | AJ5: >=1000 | AK5: bin4 | AL5: unemployed | AM5: bin1 | AN5: male mar/wid | AO5: bin3 | AQ5: car | AR5: bin3 | AW5: unemp/unskilled non res | AZ5: >=200
A6: duration | B6: 5 | C6: 48 | E6: =COUNTIFS(Dev_sample!B:B,">="&Binning_WOE_IV!C6,Dev_sample!U:U,0) -> 21 | F6: =COUNTIFS(Dev_sample!B:B,">="&Binning_WOE_IV!C6,Dev_sample!U:U,1) -> 24 | G6: =E6/SUM($E$2:$E$6) -> 0.043298969 | H6: =F6/SUM($F$2:$F$6) -> 0.11162791 | I6: =LN(Binning_WOE_IV!G6/Binning_WOE_IV!H6) -> -0.94704226 | J6: =(Binning_WOE_IV!G6-Binning_WOE_IV!H6)*Binning_WOE_IV!I6 -> 0.064710391 | AF6: all paid | AG6: bin3 | AH6: used car | AI6: bin5 | AJ6: 100<=X<500 | AK6: bin3 | AL6: <1 | AM6: bin2
A7: credit_amount | B7: 1 | C7: 0 | D7: 1000 | E7: =COUNTIFS(Dev_sample!E:E,">="&Binning_WOE_IV!C7,Dev_sample!E:E,"<"&Binning_WOE_IV!D7,Dev_sample!U:U,0) -> 54 | F7: =COUNTIFS(Dev_sample!E:E,">="&Binning_WOE_IV!C7,Dev_sample!E:E,"<"&Binning_WOE_IV!D7,Dev_sample!U:U,1) -> 23 | G7: =E7/SUM($E$7:$E$12) -> 0.11134021 | H7: =F7/SUM($F$7:$F$12) -> 0.10697674 | I7: =LN(G7/H7) -> 0.039978968 | J7: =(G7-H7)*I7 -> 0.00017444671 | K7: =SUM(J7:J12) -> 0.084625243 | L7: accept | AH7: business | AI7: bin6
A8: credit_amount | B8: 2 | C8: 1000 | D8: 2000 | E8: =COUNTIFS(Dev_sample!E:E,">="&Binning_WOE_IV!C8,Dev_sample!E:E,"<"&Binning_WOE_IV!D8,Dev_sample!U:U,0) -> 159 | F8: =COUNTIFS(Dev_sample!E:E,">="&Binning_WOE_IV!C8,Dev_sample!E:E,"<"&Binning_WOE_IV!D8,Dev_sample!U:U,1) -> 60 | G8: =E8/SUM($E$7:$E$12) -> 0.32783505 | H8: =F8/SUM($F$7:$F$12) -> 0.27906977 | I8: =LN(G8/H8) -> 0.16104878 | J8: =(G8-H8)*I8 -> 0.0078535894 | AH8: domestic appliance | AI8: bin3
A9: credit_amount | B9: 3 | C9: 2000 | D9: 3000 | E9: =COUNTIFS(Dev_sample!E:E,">="&Binning_WOE_IV!C9,Dev_sample!E:E,"<"&Binning_WOE_IV!D9,Dev_sample!U:U,0) -> 97 | F9: =COUNTIFS(Dev_sample!E:E,">="&Binning_WOE_IV!C9,Dev_sample!E:E,"<"&Binning_WOE_IV!D9,Dev_sample!U:U,1) -> 38 | G9: =E9/SUM($E$7:$E$12) -> 0.2 | H9: =F9/SUM($F$7:$F$12) -> 0.17674419 | I9: =LN(G9/H9) -> 0.12361396 | J9: =(G9-H9)*I9 -> 0.0028747432 | AH9: repairs | AI9: bin5
A10: credit_amount | B10: 4 | C10: 3000 | D10: 5000 | E10: =COUNTIFS(Dev_sample!E:E,">="&Binning_WOE_IV!C10,Dev_sample!E:E,"<"&Binning_WOE_IV!D10,Dev_sample!U:U,0) -> 99 | F10: =COUNTIFS(Dev_sample!E:E,">="&Binning_WOE_IV!C10,Dev_sample!E:E,"<"&Binning_WOE_IV!D10,Dev_sample!U:U,1) -> 42 | G10: =E10/SUM($E$7:$E$12) -> 0.20412371 | H10: =F10/SUM($F$7:$F$12) -> 0.19534884 | I10: =LN(G10/H10) -> 0.043939369 | J10: =(G10-H10)*I10 -> 0.00038556243 | AH10: other | AI10: bin1
A11: credit_amount | B11: 5 | C11: 5000 | D11: 8000 | E11: =COUNTIFS(Dev_sample!E:E,">="&Binning_WOE_IV!C11,Dev_sample!E:E,"<"&Binning_WOE_IV!D11,Dev_sample!U:U,0) -> 55 | F11: =COUNTIFS(Dev_sample!E:E,">="&Binning_WOE_IV!C11,Dev_sample!E:E,"<"&Binning_WOE_IV!D11,Dev_sample!U:U,1) -> 27 | G11: =E11/SUM($E$7:$E$12) -> 0.11340206 | H11: =F11/SUM($F$7:$F$12) -> 0.1255814 | I11: =LN(G11/H11) -> -0.10201454 | J11: =(G11-H11)*I11 -> 0.0012424691 | AH11: retraining | AI11: bin2
A12: credit_amount | B12: 6 | C12: 8000 | E12: =COUNTIFS(Dev_sample!E:E,">="&Binning_WOE_IV!C12,Dev_sample!U:U,0) -> 21 | F12: =COUNTIFS(Dev_sample!E:E,">="&Binning_WOE_IV!C12,Dev_sample!U:U,1) -> 25 | G12: =E12/SUM($E$7:$E$12) -> 0.043298969 | H12: =F12/SUM($F$7:$F$12) -> 0.11627907 | I12: =LN(G12/H12) -> -0.98786425 | J12: =(G12-H12)*I12 -> 0.072094432
A13: age | B13: 1 | C13: 0 | D13: 26 | E13: =COUNTIFS(Dev_sample!M:M,">="&Binning_WOE_IV!C13,Dev_sample!M:M,"<"&Binning_WOE_IV!D13,Dev_sample!U:U,0) -> 86 | F13: =COUNTIFS(Dev_sample!M:M,">="&Binning_WOE_IV!C13,Dev_sample!M:M,"<"&Binning_WOE_IV!D13,Dev_sample!U:U,1) -> 57 | G13: =E13/SUM($E$13:$E$18) -> 0.17731959 | H13: =F13/SUM(($F$13:$F$18)) -> 0.26511628 | I13: =LN(G13/H13) -> -0.40221483 | J13: =(G13-H13)*I13 -> 0.035313132 | K13: =SUM(J13:J18) -> 0.089177009 | L13: accept
A14: age | B14: 2 | C14: 26 | D14: 30 | E14: =COUNTIFS(Dev_sample!M:M,">="&Binning_WOE_IV!C14,Dev_sample!M:M,"<"&Binning_WOE_IV!D14,Dev_sample!U:U,0) -> 83 | F14: =COUNTIFS(Dev_sample!M:M,">="&Binning_WOE_IV!C14,Dev_sample!M:M,"<"&Binning_WOE_IV!D14,Dev_sample!U:U,1) -> 42 | G14: =E14/SUM($E$13:$E$18) -> 0.17113402 | H14: =F14/SUM(($F$13:$F$18)) -> 0.19534884 | I14: =LN(G14/H14) -> -0.13233987 | J14: =(G14-H14)*I14 -> 0.0032045858
A15: age | B15: 3 | C15: 30 | D15: 36 | E15: =COUNTIFS(Dev_sample!M:M,">="&Binning_WOE_IV!C15,Dev_sample!M:M,"<"&Binning_WOE_IV!D15,Dev_sample!U:U,0) -> 101 | F15: =COUNTIFS(Dev_sample!M:M,">="&Binning_WOE_IV!C15,Dev_sample!M:M,"<"&Binning_WOE_IV!D15,Dev_sample!U:U,1) -> 49 | G15: =E15/SUM($E$13:$E$18) -> 0.20824742 | H15: =F15/SUM(($F$13:$F$18)) -> 0.22790698 | I15: =LN(G15/H15) -> -0.090210644 | J15: =(G15-H15)*I15 -> 0.001773501
A16: age | B16: 4 | C16: 36 | D16: 45 | E16: =COUNTIFS(Dev_sample!M:M,">="&Binning_WOE_IV!C16,Dev_sample!M:M,"<"&Binning_WOE_IV!D16,Dev_sample!U:U,0) -> 107 | F16: =COUNTIFS(Dev_sample!M:M,">="&Binning_WOE_IV!C16,Dev_sample!M:M,"<"&Binning_WOE_IV!D16,Dev_sample!U:U,1) -> 36 | G16: =E16/SUM($E$13:$E$18) -> 0.22061856 | H16: =F16/SUM(($F$13:$F$18)) -> 0.16744186 | I16: =LN(G16/H16) -> 0.27579903 | J16: =(G16-H16)*I16 -> 0.014666081
A17: age | B17: 5 | C17: 45 | D17: 60 | E17: =COUNTIFS(Dev_sample!M:M,">="&Binning_WOE_IV!C17,Dev_sample!M:M,"<"&Binning_WOE_IV!D17,Dev_sample!U:U,0) -> 79 | F17: =COUNTIFS(Dev_sample!M:M,">="&Binning_WOE_IV!C17,Dev_sample!M:M,"<"&Binning_WOE_IV!D17,Dev_sample!U:U,1) -> 23 | G17: =E17/SUM($E$13:$E$18) -> 0.1628866 | H17: =F17/SUM(($F$13:$F$18)) -> 0.10697674 | I17: =LN(G17/H17) -> 0.42044277 | J17: =(G17-H17)*I17 -> 0.023506894
A18: age | B18: 6 | C18: 60 | E18: =COUNTIFS(Dev_sample!M:M,">="&Binning_WOE_IV!C18,Dev_sample!U:U,0) -> 29 | F18: =COUNTIFS(Dev_sample!M:M,">="&C18,Dev_sample!U:U,1) -> 8 | G18: =E18/SUM($E$13:$E$18) -> 0.059793814 | H18: =F18/SUM(($F$13:$F$18)) -> 0.037209302 | I18: =LN(G18/H18) -> 0.47434343 | J18: =(G18-H18)*I18 -> 0.010712815
A19: installment_commitment | B19: 1 | C19: 1 | D19: 2 | E19: =COUNTIFS(Dev_sample!H:H,">="&Binning_WOE_IV!C19,Dev_sample!H:H,"<"&Binning_WOE_IV!D19,Dev_sample!U:U,0) -> 75 | F19: =COUNTIFS(Dev_sample!H:H,">="&Binning_WOE_IV!C19,Dev_sample!H:H,"<"&Binning_WOE_IV!D19,Dev_sample!U:U,1) -> 28 | G19: =E19/SUM($E$19:$E$21) -> 0.15463918 | H19: =F19/SUM($F$19:$F$21) -> 0.13023256 | I19: =LN(G19/H19) -> 0.17177274 | J19: =(G19-H19)*I19 -> 0.0041923915 | K19: =SUM(J19:J21) -> 0.0050929839 | L19: reject
A20: installment_commitment | B20: 2 | C20: 2 | D20: 3 | E20: =COUNTIFS(Dev_sample!H:H,">="&Binning_WOE_IV!C20,Dev_sample!H:H,"<"&Binning_WOE_IV!D20,Dev_sample!U:U,0) -> 109 | F20: =COUNTIFS(Dev_sample!H:H,">="&Binning_WOE_IV!C20,Dev_sample!H:H,"<"&Binning_WOE_IV!D20,Dev_sample!U:U,1) -> 51 | G20: =E20/SUM($E$19:$E$21) -> 0.22474227 | H20: =F20/SUM($F$19:$F$21) -> 0.2372093 | I20: =LN(G20/H20) -> -0.053988613 | J20: =(G20-H20)*I20 -> 0.00067307789
A21: installment_commitment | B21: 3 | C21: 3 | E21: =COUNTIFS(Dev_sample!H:H,">="&Binning_WOE_IV!C21,Dev_sample!U:U,0) -> 301 | F21: =COUNTIFS(Dev_sample!H:H,">="&Binning_WOE_IV!C21,Dev_sample!U:U,1) -> 136 | G21: =E21/SUM($E$19:$E$21) -> 0.62061856 | H21: =F21/SUM($F$19:$F$21) -> 0.63255814 | I21: =LN(G21/H21) -> -0.019055484 | J21: =(G21-H21)*I21 -> 0.00022751453
A22: residence_since | B22: 1 | C22: 1 | D22: 2 | E22: =COUNTIFS(Dev_sample!K:K,">="&Binning_WOE_IV!C22,Dev_sample!K:K,"<"&Binning_WOE_IV!D22,Dev_sample!U:U,0) -> 63 | F22: =COUNTIFS(Dev_sample!K:K,">="&Binning_WOE_IV!C22,Dev_sample!K:K,"<"&Binning_WOE_IV!D22,Dev_sample!U:U,1) -> 22 | G22: =E22/SUM($E$22:$E$24) -> 0.12989691 | H22: =F22/SUM($F$22:$F$24) -> 0.10232558 | I22: =LN(G22/H22) -> 0.23858141 | J22: =(G22-H22)*I22 -> 0.0065780058 | K22: =SUM(J22:J24) -> 0.011789573 | L22: reject
A23: residence_since | B23: 2 | C23: 2 | D23: 4 | E23: =COUNTIFS(Dev_sample!K:K,">="&Binning_WOE_IV!C23,Dev_sample!K:K,"<"&Binning_WOE_IV!D23,Dev_sample!U:U,0) -> 217 | F23: =COUNTIFS(Dev_sample!K:K,">="&Binning_WOE_IV!C23,Dev_sample!K:K,"<"&Binning_WOE_IV!D23,Dev_sample!U:U,1) -> 106 | G23: =E23/SUM($E$22:$E$24) -> 0.44742268 | H23: =F23/SUM($F$22:$F$24) -> 0.49302326 | I23: =LN(G23/H23) -> -0.097052603 | J23: =(G23-H23)*I23 -> 0.0044256546
A24: residence_since | B24: 3 | C24: 4 | E24: =COUNTIFS(Dev_sample!K:K,">="&Binning_WOE_IV!C24,Dev_sample!U:U,0) -> 205 | F24: =COUNTIFS(Dev_sample!K:K,">="&Binning_WOE_IV!C24,Dev_sample!U:U,1) -> 87 | G24: =E24/SUM($E$22:$E$24) -> 0.42268041 | H24: =F24/SUM($F$22:$F$24) -> 0.40465116 | I24: =LN(G24/H24) -> 0.043590998 | J24: =(G24-H24)*I24 -> 0.00078591298
A25: existing_credits | B25: 1 | C25: 1 | D25: 2 | E25: =COUNTIFS(Dev_sample!P:P,">="&Binning_WOE_IV!C25,Dev_sample!P:P,"<"&Binning_WOE_IV!D25,Dev_sample!U:U,0) -> 313 | F25: =COUNTIFS(Dev_sample!P:P,">="&Binning_WOE_IV!C25,Dev_sample!P:P,"<"&Binning_WOE_IV!D25,Dev_sample!U:U,1) -> 137 | G25: =E25/SUM($E$25:$E$26) -> 0.64536082 | H25: =F25/SUM($F$25:$F$26) -> 0.6372093 | I25: =LN(G25/H25) -> 0.012711402 | J25: =(G25-H25)*I25 -> 0.00010361728 | K25: =SUM(J25:J26) -> 0.00028886236 | L25: reject
A26: existing_credits | B26: 2 | C26: 2 | E26: =COUNTIFS(Dev_sample!P:P,">="&Binning_WOE_IV!C26,Dev_sample!U:U,0) -> 172 | F26: =COUNTIFS(Dev_sample!P:P,">="&Binning_WOE_IV!C26,Dev_sample!U:U,1) -> 78 | G26: =E26/SUM($E$25:$E$26) -> 0.35463918 | H26: =F26/SUM($F$25:$F$26) -> 0.3627907 | I26: =LN(G26/H26) -> -0.022725213 | J26: =(G26-H26)*I26 -> 0.00018524508
A27: num_dependents | B27: 1 | C27: 1 | D27: 2 | E27: =COUNTIFS(Dev_sample!R:R,">="&Binning_WOE_IV!C27,Dev_sample!R:R,"<"&Binning_WOE_IV!D27,Dev_sample!U:U,0) -> 407 | F27: =COUNTIFS(Dev_sample!R:R,">="&Binning_WOE_IV!C27,Dev_sample!R:R,"<"&Binning_WOE_IV!D27,Dev_sample!U:U,1) -> 178 | G27: =E27/SUM($E$27:$E$28) -> 0.83917526 | H27: =F27/SUM($F$27:$F$28) -> 0.82790698 | I27: =LN(G27/H27) -> 0.013518772 | J27: =(G27-H27)*I27 -> 0.00015233333 | K27: =SUM(J27:J28) -> 0.00091542074 | L27: reject
A28: num_dependents | B28: 2 | C28: 2 | E28: =COUNTIFS(Dev_sample!R:R,">="&Binning_WOE_IV!C28,Dev_sample!U:U,0) -> 78 | F28: =COUNTIFS(Dev_sample!R:R,">="&Binning_WOE_IV!C28,Dev_sample!U:U,1) -> 37 | G28: =E28/SUM($E$27:$E$28) -> 0.16082474 | H28: =F28/SUM($F$27:$F$28) -> 0.17209302 | I28: =LN(G28/H28) -> -0.067719949 | J28: =(G28-H28)*I28 -> 0.00076308741
A31: Categorical Variable | B31: Bin | C31: Good | D31: Bad | E31: GoodDist | F31: BadDist | G31: WOE | H31: IV_bin | I31: IV_total | J31: evaluation | K31: RC_GoodDist | L31: RC_BadDist | M31: RC_WOE | N31: RC_IV_bin | O31: RC_IV_total | P31: final evaluation
A32: checking_status | B32: <0 | C32: =COUNTIFS(Dev_sample!A:A,"="&Binning_WOE_IV!B32,Dev_sample!U:U,0) -> 103 | D32: =COUNTIFS(Dev_sample!A:A,"="&Binning_WOE_IV!B32,Dev_sample!U:U,1) -> 90 | E32: =C32/SUM($C$32:$C$35) -> 0.21237113 | F32: =D32/SUM($D$32:$D$35) -> 0.41860465 | G32: =LN(E32/F32) -> -0.67859154 | H32: =(E32-F32)*G32 -> 0.13994832 | I32: =SUM(H32:H35) -> 0.57579092 | J32: accept | K32: =C32/SUM($C$32:$C$34) -> 0.41532258 | L32: =D32/SUM($D$32:$D$34) -> 0.49723757 | M32: =LN(K32/L32) -> -0.1800124 | N32: =(K32-L32)*M32 -> 0.014745713 | O32: =SUM(N32:N34) -> 0.057345018 | P32: accept
A33: checking_status | B33: 0<=X<200 | C33: =COUNTIFS(Dev_sample!A:A,"="&Binning_WOE_IV!B33,Dev_sample!U:U,0) -> 113 | D33: =COUNTIFS(Dev_sample!A:A,"="&Binning_WOE_IV!B33,Dev_sample!U:U,1) -> 79 | E33: =C33/SUM($C$32:$C$35) -> 0.23298969 | F33: =D33/SUM($D$32:$D$35) -> 0.36744186 | G33: =LN(E33/F33) -> -0.4555709 | H33: =(E33-F33)*G33 -> 0.061252496 | K33: =C33/SUM($C$32:$C$34) -> 0.45564516 | L33: =D33/SUM($D$32:$D$34) -> 0.43646409 | M33: =LN(K33/L33) -> 0.043008251 | N33: =(K33-L33)*M33 -> 0.0008249444
A34: checking_status | B34: >=200 | C34: =COUNTIFS(Dev_sample!A:A,"="&Binning_WOE_IV!B34,Dev_sample!U:U,0) -> 32 | D34: =COUNTIFS(Dev_sample!A:A,"="&Binning_WOE_IV!B34,Dev_sample!U:U,1) -> 12 | E34: =C34/SUM($C$32:$C$35) -> 0.065979381 | F34: =D34/SUM($D$32:$D$35) -> 0.055813953 | G34: =LN(E34/F34) -> 0.16731839 | H34: =(E34-F34)*G34 -> 0.001700863 | K34: =C34/SUM($C$32:$C$34) -> 0.12903226 | L34: =D34/SUM($D$32:$D$34) -> 0.066298343 | M34: =LN(K34/L34) -> 0.66589754 | N34: =(K34-L34)*M34 -> 0.04177436
A35: checking_status | B35: no checking | C35: =COUNTIFS(Dev_sample!A:A,"="&Binning_WOE_IV!B35,Dev_sample!U:U,0) -> 237 | D35: =COUNTIFS(Dev_sample!A:A,"="&Binning_WOE_IV!B35,Dev_sample!U:U,1) -> 34 | E35: =C35/SUM($C$32:$C$35) -> 0.48865979 | F35: =D35/SUM($D$32:$D$35) -> 0.15813953 | G35: =LN(E35/F35) -> 1.1281888 | H35: =(E35-F35)*G35 -> 0.37288924
A36: credit_history | B36: critical/other existing credit | C36: =COUNTIFS(Dev_sample!C:C,AF2,Dev_sample!U:U,0) -> 157 | D36: =COUNTIFS(Dev_sample!C:C,AF2,Dev_sample!U:U,1) -> 35 | E36: =C36/SUM($C$36:$C$38) -> 0.32371134 | F36: =D36/SUM($D$36:$D$38) -> 0.1627907 | G36: =LN(E36/F36) -> 0.68738688 | H36: =(E36-F36)*G36 -> 0.11061474 | I36: =SUM(H36:H38) -> 0.27668076 | J36: accept | R36: bin1
A37: credit_history | B37: existing paid + delayed previously | C37: =SUM(COUNTIFS(Dev_sample!C:C,AF3,Dev_sample!U:U,0),COUNTIFS(Dev_sample!C:C,AF4,Dev_sample!U:U,0)) -> 302 | D37: =SUM(COUNTIFS(Dev_sample!C:C,AF3,Dev_sample!U:U,1),COUNTIFS(Dev_sample!C:C,AF4,Dev_sample!U:U,1)) -> 140 | E37: =C37/SUM($C$36:$C$38) -> 0.62268041 | F37: =D37/SUM($D$36:$D$38) -> 0.65116279 | G37: =LN(E37/F37) -> -0.044726268 | H37: =(E37-F37)*G37 -> 0.0012739105 | R37: bin2
A38: credit_history | B38: no credits/all paid + all paid | C38: =SUM(COUNTIFS(Dev_sample!C:C,AF5,Dev_sample!U:U,0),COUNTIFS(Dev_sample!C:C,AF6,Dev_sample!U:U,0)) -> 26 | D38: =SUM(COUNTIFS(Dev_sample!C:C,AF5,Dev_sample!U:U,1),COUNTIFS(Dev_sample!C:C,AF6,Dev_sample!U:U,1)) -> 40 | E38: =C38/SUM($C$36:$C$38) -> 0.053608247 | F38: =D38/SUM($D$36:$D$38) -> 0.18604651 | G38: =LN(E38/F38) -> -1.2442938 | H38: =(E38-F38)*G38 -> 0.16479211 | R38: bin3
A39: purpose | B39: radio/tv + other | C39: =SUM(COUNTIFS(Dev_sample!D:D,AH2,Dev_sample!U:U,0),COUNTIFS(Dev_sample!D:D,Binning_WOE_IV!AH10,Dev_sample!U:U,0)) -> 158 | D39: =SUM(COUNTIFS(Dev_sample!D:D,AH2,Dev_sample!U:U,1),COUNTIFS(Dev_sample!D:D,Binning_WOE_IV!AH10,Dev_sample!U:U,1)) -> 46 | E39: =C39/SUM($C$39:$C$44) -> 0.3257732 | F39: =D39/SUM($D$39:$D$44) -> 0.21395349 | G39: =LN(E39/F39) -> 0.42044277 | H39: =(E39-F39)*G39 -> 0.047013788 | I39: =SUM(H39:H44) -> 0.13223713 | J39: accept | R39: bin1
A40: purpose | B40: education + retraining | C40: =SUM(COUNTIFS(Dev_sample!D:D,AH3,Dev_sample!U:U,0),COUNTIFS(Dev_sample!D:D,Binning_WOE_IV!AH11,Dev_sample!U:U,0)) -> 25 | D40: =SUM(COUNTIFS(Dev_sample!D:D,AH3,Dev_sample!U:U,1),COUNTIFS(Dev_sample!D:D,Binning_WOE_IV!AH11,Dev_sample!U:U,1)) -> 15 | E40: =C40/SUM($C$39:$C$44) -> 0.051546392 | F40: =D40/SUM($D$39:$D$44) -> 0.069767442 | G40: =LN(E40/F40) -> -0.30268524 | H40: =(E40-F40)*G40 -> 0.0055152429 | R40: bin2
A41: purpose | B41: furniture/equipment + domestic appliances | C41: =SUM(COUNTIFS(Dev_sample!D:D,AH4,Dev_sample!U:U,0),COUNTIFS(Dev_sample!D:D,Binning_WOE_IV!AH8,Dev_sample!U:U,0)) -> 98 | D41: =SUM(COUNTIFS(Dev_sample!D:D,AH4,Dev_sample!U:U,1),COUNTIFS(Dev_sample!D:D,Binning_WOE_IV!AH8,Dev_sample!U:U,1)) -> 46 | E41: =C41/SUM($C$39:$C$44) -> 0.20206186 | F41: =D41/SUM($D$39:$D$44) -> 0.21395349 | G41: =LN(E41/F41) -> -0.057184781 | H41: =(E41-F41)*G41 -> 0.00068002041 | R41: bin3
A42: purpose | B42: new car | C42: =COUNTIFS(Dev_sample!D:D,Binning_WOE_IV!B42,Dev_sample!U:U,0) -> 95 | D42: =COUNTIFS(Dev_sample!D:D,Binning_WOE_IV!B42,Dev_sample!U:U,1) -> 61 | E42: =C42/SUM($C$39:$C$44) -> 0.19587629 | F42: =D42/SUM($D$39:$D$44) -> 0.28372093 | G42: =LN(E42/F42) -> -0.37050784 | H42: =(E42-F42)*G42 -> 0.032547128 | R42: bin4
...

Sheet TRAIN_DATA
A1: checking_status | B1: duration | C1: credit_history | D1: purpose | E1: credit_amount | F1: savings_status | G1: employment | H1: installment_commitment | I1: personal_status | J1: other_parties | K1: residence_since | L1: property_magnitude | M1: age | N1: other_payment_plans | O1: housing | P1: existing_credits | Q1: job | R1: num_dependents | S1: own_telephone | T1: foreign_worker | U1: class | V1: duration_WOE | W1: credit_amount_WOE | X1: age_WOE | Y1: checking_status_WOE | Z1: credit_history_WOE | AA1: purpose_WOE | AB1: savings_status_WOE | AC1: employment_WOE | AD1: personal_status_WOE | AE1: property_magnitude_WOE | AF1: other_payments_plans_WOE | AG1: housing_WOE | AH1: duration_beta | AI1: credit_amount_beta | AJ1: age_beta | AK1: checking_status_beta | AL1: credit_history_beta | AM1: purpose_beta | AN1: savings_status_beta | AO1: employment_beta | AP1: personal_status_beta | AQ1: property_magnitude_beta | AR1: other_payments_plans_beta | AS1: housing_beta | AT1: LOGIT_PRED | AU1: Probability_of_Default | AV1: Log_Loss | AW1: GOOD_FLAG | AX1: BAD_FLAG | AY1: CUM_GOOD | AZ1: CUM_BAD | BA1: CUM_GOOD % | BB1: CUM_BAD % | BC1: KS | BD1: True_Positive_Rate | BE1: False_Positive_Rate | BF1: duration_score | BG1: credit_amount_score | BH1: age_score | BI1: checking_status_score | BJ1: credit_history_score | BK1: purpose_score | BL1: savings_status_score | BM1: employment_score | BN1: personal_status_score | BO1: property_magnitude_score | BP1: other_payments_plans_score | BQ1: housing_score | BR1: SCORE | BS1: Decision | BT1: Decision_num
A2: 0<=X<200 | B2: 54 | C2: no credits/all paid | D2: business | E2: 15945 | F2: <100 | G2: <1 | H2: 3 | I2: male single | J2: none | K2: 4 | L2: no known property | M2: 58 | N2: none | O2: rent | P2: 1 | Q2: skilled | R2: 1 | S2: yes | T2: yes | U2: 1 | V2: =_xlfn.XLOOKUP(B2,Binning_WOE_IV!$C$2:$C$6,Binning_WOE_IV!$I$2:$I$6,"not found",-1) -> -0.94704226 | W2: =_xlfn.XLOOKUP(E2,Binning_WOE_IV!$C$7:$C$12,Binning_WOE_IV!$I$7:$I$12,"not found",-1) -> -0.98786425 | X2: =_xlfn.XLOOKUP(M2,Binning_WOE_IV!$C$13:$C$18,Binning_WOE_IV!$I$13:$I$18,"not found",-1) -> 0.42044277 | Y2: =_xlfn.XLOOKUP(A2,Binning_WOE_IV!$B$32:$B$35,Binning_WOE_IV!$G$32:$G$35,"not found",0) -> -0.4555709 | Z2: =_xlfn.XLOOKUP(_xlfn.XLOOKUP(C2,Binning_WOE_IV!$AF$2:$AF$6,Binning_WOE_IV!$AG$2:$AG$6,"not found",0),Binning_WOE_IV!$R$36:$R$38,Binning_WOE_IV!$G$36:$G$38,"not found",0) -> -1.2442938 | AA2: {=_xlfn.SWITCH(D2,"radio/tv",Binning_WOE_IV!$G$39,"other",Binning_WOE_IV!$G$39,"education",Binning_WOE_IV!$G$40,"retraining",Binning_WOE_IV!$G$40,"furniture/equipment",Binning_WOE_IV!$G$41,"domestic appliance",Binning_WOE_IV!$G$41,"new car",Binning_WOE_IV!$G$42,"used car",Binning_WOE_IV!$G$43,"repairs",Binning_WOE_IV!$G$43,"business",Binning_WOE_IV!$G$44,"not found")} -> -0.47176157 | AB2: =_xlfn.LET(_xlpm.b,_xlfn.XLOOKUP(F2,Binning_WOE_IV!$AJ$2:$AJ$6,Binning_WOE_IV!$AK$2:$AK$6,"not found",0),IF(_xlpm.b="bin1",_xlfn.XLOOKUP(_xlpm.b,Binning_WOE_IV!$R$45:$R$48,Binning_WOE_IV!$G$45:$G$48,"not found",0),_xlfn.XLOOKUP(_xlpm.b,Binning_WOE_IV!$R$45:$R$48,Binning_WOE_IV!$G$45:$G$48,"not found",0))) -> -0.23980372 | AC2: =_xlfn.LET(_xlpm.b,_xlfn.XLOOKUP(G2,Binning_WOE_IV!$AL$2:$AL$6,Binning_WOE_IV!$AM$2:$AM$6,"not found",0),IF(_xlpm.b="bin1",_xlfn.XLOOKUP(_xlpm.b,Binning_WOE_IV!$R$49:$R$52,Binning_WOE_IV!$G$49:$G$52,"not found",0),_xlfn.XLOOKUP(_xlpm.b,Binning_WOE_IV!$R$49:$R$52,Binning_WOE_IV!$G$49:$G$52,"not found",0))) -> -0.49142736 | AD2: =_xlfn.XLOOKUP(_xlfn.XLOOKUP(I2,Binning_WOE_IV!$AN$2:$AN$5,Binning_WOE_IV!$AO$2:$AO$5,"not found",0),Binning_WOE_IV!$R$53:$R$55,Binning_WOE_IV!$G$53:$G$55,"not found",0) -> 0.18111171 | AE2: =_xlfn.LET(_xlpm.b,_xlfn.XLOOKUP(L2,Binning_WOE_IV!$AQ$2:$AQ$5,Binning_WOE_IV!$AR$2:$AR$5,"not found",0),IF(_xlpm.b="bin4",_xlfn.XLOOKUP(_xlpm.b,Binning_WOE_IV!$R$58:$R$61,Binning_WOE_IV!$G$58:$G$61,"not found",0),_xlfn.XLOOKUP(_xlpm.b,Binning_WOE_IV!$R$58:$R$61,Binning_WOE_IV!$G$58:$G$61,"not found",0))) -> -0.56219643 | AF2: =_xlfn.XLOOKUP(_xlfn.XLOOKUP(N2,Binning_WOE_IV!$AS$2:$AS$4,Binning_WOE_IV!$AT$2:$AT$4,"not found",0),Binning_WOE_IV!$R$62:$R$63,Binning_WOE_IV!$G$62:$G$63,"not found",0) -> 0.12957806 | AG2: =_xlfn.XLOOKUP(_xlfn.XLOOKUP(O2,Binning_WOE_IV!$AU$2:$AU$4,Binning_WOE_IV!$AV$2:$AV$4,"not found",0),Binning_WOE_IV!$R$64:$R$65,Binning_WOE_IV!$G$64:$G$65,"not found",0) -> -0.49192724 | AH2: =V2*TRAIN_SUMMARY!$C$3 -> 0.74681908 | AI2: =W2*TRAIN_SUMMARY!$C$4 -> 0.49301773 | AJ2: =X2*TRAIN_SUMMARY!$C$5 -> -0.26777415 | AK2: =Y2*TRAIN_SUMMARY!$C$6 -> 0.3570927 | AL2: =Z2*TRAIN_SUMMARY!$C$7 -> 0.68384 | AM2: =AA2*TRAIN_SUMMARY!$C$8 -> 0.48833778 | AN2: =AB2*TRAIN_SUMMARY!$C$9 -> 0.17108449 | AO2: =AC2*TRAIN_SUMMARY!$C$10 -> 0.28670892 | AP2: =AD2*TRAIN_SUMMARY!$C$11 -> -0.21458248 | AQ2: =AE2*TRAIN_SUMMARY!$C$12 -> 0.30495501 | AR2: =AF2*TRAIN_SUMMARY!$C$13 -> -0.079424742 | AS2: =AG2*TRAIN_SUMMARY!$C$14 -> 0.186008 | AT2: =TRAIN_SUMMARY!$C$2+SUM(AH2:AS2) -> 2.3346815 | AU2: =1/(1+EXP(-AT2)) -> 0.91170891 | AV2: =-((U2*LN(AU2))+(1-U2)*LN(1-AU2)) -> 0.092434521 | AW2: =IF(U2=0,1,0) -> 0 | AX2: =IF(U2=1,1,0) -> 1 | AY2: =AW2 -> 0 | AZ2: =AX2 -> 1 | BA2: =AY2/SUM($AW$2:$AW$701) -> 0 | BB2: =AZ2/SUM($AX$2:$AX$701) -> 0.0046511628 | BC2: =ABS(BA2-BB2) -> 0.0046511628 | BD2: =BB2 -> 0.0046511628 | BE2: =BA2 -> 0 | BF2: =VLOOKUP(AH2,POINTS_TABLE!$D$2:$E$6,2,FALSE) -> 32.322965 | BG2: =VLOOKUP(AI2,POINTS_TABLE!$D$7:$E$12,2,FALSE) -> 21.338227 | BH2: =VLOOKUP(AJ2,POINTS_TABLE!$D$13:$E$18,2,FALSE) -> -11.589493 | BI2: =VLOOKUP(AK2,POINTS_TABLE!$D$21:$E$24,2,FALSE) -> 15.455276 | BJ2: =VLOOKUP(AL2,POINTS_TABLE!$D$25:$E$27,2,FALSE) -> 29.597177 | BK2: =VLOOKUP(AM2,POINTS_TABLE!$D$28:$E$33,2,FALSE) -> 21.135675 | BL2: =VLOOKUP(AN2,POINTS_TABLE!$D$34:$E$37,2,FALSE) -> 7.4046822 | BM2: =VLOOKUP(AO2,POINTS_TABLE!$D$38:$E$41,2,FALSE) -> 12.409006 | BN2: =VLOOKUP(AP2,POINTS_TABLE!$D$42:$E$44,2,FALSE) -> -9.2873124 | BO2: =VLOOKUP(AQ2,POINTS_TABLE!$D$45:$E$48,2,FALSE) -> 13.198713 | BP2: =VLOOKUP(AR2,POINTS_TABLE!$D$49:$E$50,2,FALSE) -> -3.4375704 | BQ2: =VLOOKUP(AS2,POINTS_TABLE!$D$51:$E$52,2,FALSE) -> 8.0505844 | BR2: =ROUND(SCORECARD_SCALLING!$C$6-SUM(BF2:BQ2)-TRAIN_SUMMARY!$C$2*SCORECARD_SCALLING!$C$5,0) -> 369 | BS2: =IF(BR2>=580,"Accept",IF(AND(BR2>=500,BR2<580),"Manual review","Reject")) -> Reject | BT2: =IF(BS2="Reject",1,IF(BS2="Manual review",2,3)) -> 1
A3: 0<=X<200 | B3: 48 | C3: no credits/all paid | D3: business | E3: 14421 | F3: <100 | G3: 1<=X<4 | H3: 2 | I3: male single | J3: none | K3: 2 | L3: car | M3: 25 | N3: none | O3: own | P3: 1 | Q3: skilled | R3: 1 | S3: yes | T3: yes | U3: 1 | V3: =_xlfn.XLOOKUP(B3,Binning_WOE_IV!$C$2:$C$6,Binning_WOE_IV!$I$2:$I$6,"not found",-1) -> -0.94704226 | W3: =_xlfn.XLOOKUP(E3,Binning_WOE_IV!$C$7:$C$12,Binning_WOE_IV!$I$7:$I$12,"not found",-1) -> -0.98786425 | X3: =_xlfn.XLOOKUP(M3,Binning_WOE_IV!$C$13:$C$18,Binning_WOE_IV!$I$13:$I$18,"not found",-1) -> -0.40221483 | Y3: =_xlfn.XLOOKUP(A3,Binning_WOE_IV!$B$32:$B$35,Binning_WOE_IV!$G$32:$G$35,"not found",0) -> -0.4555709 | Z3: =_xlfn.XLOOKUP(_xlfn.XLOOKUP(C3,Binning_WOE_IV!$AF$2:$AF$6,Binning_WOE_IV!$AG$2:$AG$6,"not found",0),Binning_WOE_IV!$R$36:$R$38,Binning_WOE_IV!$G$36:$G$38,"not found",0) -> -1.2442938 | AA3: {=_xlfn.SWITCH(D3,"radio/tv",Binning_WOE_IV!$G$39,"other",Binning_WOE_IV!$G$39,"education",Binning_WOE_IV!$G$40,"retraining",Binning_WOE_IV!$G$40,"furniture/equipment",Binning_WOE_IV!$G$41,"domestic appliance",Binning_WOE_IV!$G$41,"new car",Binning_WOE_IV!$G$42,"used car",Binning_WOE_IV!$G$43,"repairs",Binning_WOE_IV!$G$43,"business",Binning_WOE_IV!$G$44,"not found")} -> -0.47176157 | AB3: =_xlfn.LET(_xlpm.b,_xlfn.XLOOKUP(F3,Binning_WOE_IV!$AJ$2:$AJ$6,Binning_WOE_IV!$AK$2:$AK$6,"not found",0),IF(_xlpm.b="bin1",_xlfn.XLOOKUP(_xlpm.b,Binning_WOE_IV!$R$45:$R$48,Binning_WOE_IV!$G$45:$G$48,"not found",0),_xlfn.XLOOKUP(_xlpm.b,Binning_WOE_IV!$R$45:$R$48,Binning_WOE_IV!$G$45:$G$48,"not found",0))) -> -0.23980372 | AC3: =_xlfn.LET(_xlpm.b,_xlfn.XLOOKUP(G3,Binning_WOE_IV!$AL$2:$AL$6,Binning_WOE_IV!$AM$2:$AM$6,"not found",0),IF(_xlpm.b="bin1",_xlfn.XLOOKUP(_xlpm.b,Binning_WOE_IV!$R$49:$R$52,Binning_WOE_IV!$G$49:$G$52,"not found",0),_xlfn.XLOOKUP(_xlpm.b,Binning_WOE_IV!$R$49:$R$52,Binning_WOE_IV!$G$49:$G$52,"not found",0))) -> -0.082142469 | AD3: =_xlfn.XLOOKUP(_xlfn.XLOOKUP(I3,Binning_WOE_IV!$AN$2:$AN$5,Binning_WOE_IV!$AO$2:$AO$5,"not found",0),Binning_WOE_IV!$R$53:$R$55,Binning_WOE_IV!$G$53:$G$55,"not found",0) -> 0.18111171 | AE3: =_xlfn.LET(_xlpm.b,_xlfn.XLOOKUP(L3,Binning_WOE_IV!$AQ$2:$AQ$5,Binning_WOE_IV!$AR$2:$AR$5,"not found",0),IF(_xlpm.b="bin4",_xlfn.XLOOKUP(_xlpm.b,Binning_WOE_IV!$R$58:$R$61,Binning_WOE_IV!$G$58:$G$61,"not found",0),_xlfn.XLOOKUP(_xlpm.b,Binning_WOE_IV!$R$58:$R$61,Binning_WOE_IV!$G$58:$G$61,"not found",0))) -> -0.11389117 | AF3: =_xlfn.XLOOKUP(_xlfn.XLOOKUP(N3,Binning_WOE_IV!$AS$2:$AS$4,Binning_WOE_IV!$AT$2:$AT$4,"not found",0),Binning_WOE_IV!$R$62:$R$63,Binning_WOE_IV!$G$62:$G$63,"not found",0) -> 0.12957806 | AG3: =_xlfn.XLOOKUP(_xlfn.XLOOKUP(O3,Binning_WOE_IV!$AU$2:$AU$4,Binning_WOE_IV!$AV$2:$AV$4,"not found",0),Binning_WOE_IV!$R$64:$R$65,Binning_WOE_IV!$G$64:$G$65,"not found",0) -> 0.23435623 | AH3: =V3*TRAIN_SUMMARY!$C$3 -> 0.74681908 | AI3: =W3*TRAIN_SUMMARY!$C$4 -> 0.49301773 | AJ3: =X3*TRAIN_SUMMARY!$C$5 -> 0.25616503 | AK3: =Y3*TRAIN_SUMMARY!$C$6 -> 0.3570927 | AL3: =Z3*TRAIN_SUMMARY!$C$7 -> 0.68384 | AM3: =AA3*TRAIN_SUMMARY!$C$8 -> 0.48833778 | AN3: =AB3*TRAIN_SUMMARY!$C$9 -> 0.17108449 | AO3: =AC3*TRAIN_SUMMARY!$C$10 -> 0.047923621 | AP3: =AD3*TRAIN_SUMMARY!$C$11 -> -0.21458248 | AQ3: =AE3*TRAIN_SUMMARY!$C$12 -> 0.061778554 | AR3: =AF3*TRAIN_SUMMARY!$C$13 -> -0.079424742 | AS3: =AG3*TRAIN_SUMMARY!$C$14 -> -0.088615 | AT3: =TRAIN_SUMMARY!$C$2+SUM(AH3:AS3) -> 2.102036 | AU3: =1/(1+EXP(-AT3)) -> 0.89110091 | AV3: =-((U3*LN(AU3))+(1-U3)*LN(1-AU3)) -> 0.11529761 | AW3: =IF(U3=0,1,0) -> 0 | AX3: =IF(U3=1,1,0) -> 1 | AY3: =AY2+AW3 -> 0 | AZ3: =AZ2+AX3 -> 2 | BA3: =AY3/SUM($AW$2:$AW$701) -> 0 | BB3: =AZ3/SUM($AX$2:$AX$701) -> 0.0093023256 | BC3: =ABS(BA3-BB3) -> 0.0093023256 | BD3: =BB3 -> 0.0093023256 | BE3: =BA3 -> 0 | BF3: =VLOOKUP(AH3,POINTS_TABLE!$D$2:$E$6,2,FALSE) -> 32.322965 | BG3: =VLOOKUP(AI3,POINTS_TABLE!$D$7:$E$12,2,FALSE) -> 21.338227 | BH3: =VLOOKUP(AJ3,POINTS_TABLE!$D$13:$E$18,2,FALSE) -> 11.087041 | BI3: =VLOOKUP(AK3,POINTS_TABLE!$D$21:$E$24,2,FALSE) -> 15.455276 | BJ3: =VLOOKUP(AL3,POINTS_TABLE!$D$25:$E$27,2,FALSE) -> 29.597177 | BK3: =VLOOKUP(AM3,POINTS_TABLE!$D$28:$E$33,2,FALSE) -> 21.135675 | BL3: =VLOOKUP(AN3,POINTS_TABLE!$D$34:$E$37,2,FALSE) -> 7.4046822 | BM3: =VLOOKUP(AO3,POINTS_TABLE!$D$38:$E$41,2,FALSE) -> 2.0741751 | BN3: =VLOOKUP(AP3,POINTS_TABLE!$D$42:$E$44,2,FALSE) -> -9.2873124 | BO3: =VLOOKUP(AQ3,POINTS_TABLE!$D$45:$E$48,2,FALSE) -> 2.6738284 | BP3: =VLOOKUP(AR3,POINTS_TABLE!$D$49:$E$50,2,FALSE) -> -3.4375704 | BQ3: =VLOOKUP(AS3,POINTS_TABLE!$D$51:$E$52,2,FALSE) -> -3.8353326 | BR3: =ROUND(SCORECARD_SCALLING!$C$6-SUM(BF3:BQ3)-TRAIN_SUMMARY!$C$2*SCORECARD_SCALLING!$C$5,0) -> 379 | BS3: =IF(BR3>=580,"Accept",IF(AND(BR3>=500,BR3<580),"Manual review","Reject")) -> Reject | BT3: =IF(BS3="Reject",1,IF(BS3="Manual review",2,3)) -> 1
A4: <0 | B4: 48 | C4: existing paid | D4: business | E4: 4308 | F4: <100 | G4: <1 | H4: 3 | I4: female div/dep/mar | J4: none | K4: 4 | L4: life insurance | M4: 24 | N4: none | O4: rent | P4: 1 | Q4: skilled | R4: 1 | S4: none | T4: yes | U4: 1 | V4: =_xlfn.XLOOKUP(B4,Binning_WOE_IV!$C$2:$C$6,Binning_WOE_IV!$I$2:$I$6,"not found",-1) -> -0.94704226 | W4: =_xlfn.XLOOKUP(E4,Binning_WOE_IV!$C$7:$C$12,Binning_WOE_IV!$I$7:$I$12,"not found",-1) -> 0.043939369 | X4: =_xlfn.XLOOKUP(M4,Binning_WOE_IV!$C$13:$C$18,Binning_WOE_IV!$I$13:$I$18,"not found",-1) -> -0.40221483 | Y4: =_xlfn.XLOOKUP(A4,Binning_WOE_IV!$B$32:$B$35,Binning_WOE_IV!$G$32:$G$35,"not found",0) -> -0.67859154 | Z4: =_xlfn.XLOOKUP(_xlfn.XLOOKUP(C4,Binning_WOE_IV!$AF$2:$AF$6,Binning_WOE_IV!$AG$2:$AG$6,"not found",0),Binning_WOE_IV!$R$36:$R$38,Binning_WOE_IV!$G$36:$G$38,"not found",0) -> -0.044726268 | AA4: {=_xlfn.SWITCH(D4,"radio/tv",Binning_WOE_IV!$G$39,"other",Binning_WOE_IV!$G$39,"education",Binning_WOE_IV!$G$40,"retraining",Binning_WOE_IV!$G$40,"furniture/equipment",Binning_WOE_IV!$G$41,"domestic appliance",Binning_WOE_IV!$G$41,"new car",Binning_WOE_IV!$G$42,"used car",Binning_WOE_IV!$G$43,"repairs",Binning_WOE_IV!$G$43,"business",Binning_WOE_IV!$G$44,"not found")} -> -0.47176157 | AB4: =_xlfn.LET(_xlpm.b,_xlfn.XLOOKUP(F4,Binning_WOE_IV!$AJ$2:$AJ$6,Binning_WOE_IV!$AK$2:$AK$6,"not found",0),IF(_xlpm.b="bin1",_xlfn.XLOOKUP(_xlpm.b,Binning_WOE_IV!$R$45:$R$48,Binning_WOE_IV!$G$45:$G$48,"not found",0),_xlfn.XLOOKUP(_xlpm.b,Binning_WOE_IV!$R$45:$R$48,Binning_WOE_IV!$G$45:$G$48,"not found",0))) -> -0.23980372 | AC4: =_xlfn.LET(_xlpm.b,_xlfn.XLOOKUP(G4,Binning_WOE_IV!$AL$2:$AL$6,Binning_WOE_IV!$AM$2:$AM$6,"not found",0),IF(_xlpm.b="bin1",_xlfn.XLOOKUP(_xlpm.b,Binning_WOE_IV!$R$49:$R$52,Binning_WOE_IV!$G$49:$G$52,"not found",0),_xlfn.XLOOKUP(_xlpm.b,Binning_WOE_IV!$R$49:$R$52,Binning_WOE_IV!$G$49:$G$52,"not found",0))) -> -0.49142736 | AD4: =_xlfn.XLOOKUP(_xlfn.XLOOKUP(I4,Binning_WOE_IV!$AN$2:$AN$5,Binning_WOE_IV!$AO$2:$AO$5,"not found",0),Binning_WOE_IV!$R$53:$R$55,Binning_WOE_IV!$G$53:$G$55,"not found",0) -> -0.20099342 | AE4: =_xlfn.LET(_xlpm.b,_xlfn.XLOOKUP(L4,Binning_WOE_IV!$AQ$2:$AQ$5,Binning_WOE_IV!$AR$2:$AR$5,"not found",0),IF(_xlpm.b="bin4",_xlfn.XLOOKUP(_xlpm.b,Binning_WOE_IV!$R$58:$R$61,Binning_WOE_IV!$G$58:$G$61,"not found",0),_xlfn.XLOOKUP(_xlpm.b,Binning_WOE_IV!$R$58:$R$61,Binning_WOE_IV!$G$58:$G$61,"not found",0))) -> 0.033786998 | AF4: =_xlfn.XLOOKUP(_xlfn.XLOOKUP(N4,Binning_WOE_IV!$AS$2:$AS$4,Binning_WOE_IV!$AT$2:$AT$4,"not found",0),Binning_WOE_IV!$R$62:$R$63,Binning_WOE_IV!$G$62:$G$63,"not found",0) -> 0.12957806 | AG4: =_xlfn.XLOOKUP(_xlfn.XLOOKUP(O4,Binning_WOE_IV!$AU$2:$AU$4,Binning_WOE_IV!$AV$2:$AV$4,"not found",0),Binning_WOE_IV!$R$64:$R$65,Binning_WOE_IV!$G$64:$G$65,"not found",0) -> -0.49192724 | AH4: =V4*TRAIN_SUMMARY!$C$3 -> 0.74681908 | AI4: =W4*TRAIN_SUMMARY!$C$4 -> -0.021929013 | AJ4: =X4*TRAIN_SUMMARY!$C$5 -> 0.25616503 | AK4: =Y4*TRAIN_SUMMARY!$C$6 -> 0.53190423 | AL4: =Z4*TRAIN_SUMMARY!$C$7 -> 0.024580699 | AM4: =AA4*TRAIN_SUMMARY!$C$8 -> 0.48833778 | AN4: =AB4*TRAIN_SUMMARY!$C$9 -> 0.17108449 | AO4: =AC4*TRAIN_SUMMARY!$C$10 -> 0.28670892 | AP4: =AD4*TRAIN_SUMMARY!$C$11 -> 0.23813847 | AQ4: =AE4*TRAIN_SUMMARY!$C$12 -> -0.018327249 | AR4: =AF4*TRAIN_SUMMARY!$C$13 -> -0.079424742 | AS4: =AG4*TRAIN_SUMMARY!$C$14 -> 0.186008 | AT4: =TRAIN_SUMMARY!$C$2+SUM(AH4:AS4) -> 1.9886649 | AU4: =1/(1+EXP(-AT4)) -> 0.87960182 | AV4: =-((U4*LN(AU4))+(1-U4)*LN(1-AU4)) -> 0.12828596 | AW4: =IF(U4=0,1,0) -> 0 | AX4: =IF(U4=1,1,0) -> 1 | AY4: =AY3+AW4 -> 0 | AZ4: =AZ3+AX4 -> 3 | BA4: =AY4/SUM($AW$2:$AW$701) -> 0 | BB4: =AZ4/SUM($AX$2:$AX$701) -> 0.013953488 | BC4: =ABS(BA4-BB4) -> 0.013953488 | BD4: =BB4 -> 0.013953488 | BE4: =BA4 -> 0 | BF4: =VLOOKUP(AH4,POINTS_TABLE!$D$2:$E$6,2,FALSE) -> 32.322965 | BG4: =VLOOKUP(AI4,POINTS_TABLE!$D$7:$E$12,2,FALSE) -> -0.94910635 | BH4: =VLOOKUP(AJ4,POINTS_TABLE!$D$13:$E$18,2,FALSE) -> 11.087041 | BI4: =VLOOKUP(AK4,POINTS_TABLE!$D$21:$E$24,2,FALSE) -> 23.021268 | BJ4: =VLOOKUP(AL4,POINTS_TABLE!$D$25:$E$27,2,FALSE) -> 1.0638736 | BK4: =VLOOKUP(AM4,POINTS_TABLE!$D$28:$E$33,2,FALSE) -> 21.135675 | BL4: =VLOOKUP(AN4,POINTS_TABLE!$D$34:$E$37,2,FALSE) -> 7.4046822 | BM4: =VLOOKUP(AO4,POINTS_TABLE!$D$38:$E$41,2,FALSE) -> 12.409006 | BN4: =VLOOKUP(AP4,POINTS_TABLE!$D$42:$E$44,2,FALSE) -> 10.306836 | BO4: =VLOOKUP(AQ4,POINTS_TABLE!$D$45:$E$48,2,FALSE) -> -0.79321896 | BP4: =VLOOKUP(AR4,POINTS_TABLE!$D$49:$E$50,2,FALSE) -> -3.4375704 | BQ4: =VLOOKUP(AS4,POINTS_TABLE!$D$51:$E$52,2,FALSE) -> 8.0505844 | BR4: =ROUND(SCORECARD_SCALLING!$C$6-SUM(BF4:BQ4)-TRAIN_SUMMARY!$C$2*SCORECARD_SCALLING!$C$5,0) -> 384 | BS4: =IF(BR4>=580,"Accept",IF(AND(BR4>=500,BR4<580),"Manual review","Reject")) -> Reject | BT4: =IF(BS4="Reject",1,IF(BS4="Manual review",2,3)) -> 1
A5: <0 | B5: 48 | C5: all paid | D5: business | E5: 7685 | F5: <100 | G5: 4<=X<7 | H5: 2 | I5: female div/dep/mar | J5: guarantor | K5: 4 | L5: car | M5: 37 | N5: none | O5: rent | P5: 1 | Q5: skilled | R5: 1 | S5: none | T5: yes | U5: 1 | V5: =_xlfn.XLOOKUP(B5,Binning_WOE_IV!$C$2:$C$6,Binning_WOE_IV!$I$2:$I$6,"not found",-1) -> -0.94704226 | W5: =_xlfn.XLOOKUP(E5,Binning_WOE_IV!$C$7:$C$12,Binning_WOE_IV!$I$7:$I$12,"not found",-1) -> -0.10201454 | X5: =_xlfn.XLOOKUP(M5,Binning_WOE_IV!$C$13:$C$18,Binning_WOE_IV!$I$13:$I$18,"not found",-1) -> 0.27579903 | Y5: =_xlfn.XLOOKUP(A5,Binning_WOE_IV!$B$32:$B$35,Binning_WOE_IV!$G$32:$G$35,"not found",0) -> -0.67859154 | Z5: =_xlfn.XLOOKUP(_xlfn.XLOOKUP(C5,Binning_WOE_IV!$AF$2:$AF$6,Binning_WOE_IV!$AG$2:$AG$6,"not found",0),Binning_WOE_IV!$R$36:$R$38,Binning_WOE_IV!$G$36:$G$38,"not found",0) -> -1.2442938 | AA5: {=_xlfn.SWITCH(D5,"radio/tv",Binning_WOE_IV!$G$39,"other",Binning_WOE_IV!$G$39,"education",Binning_WOE_IV!$G$40,"retraining",Binning_WOE_IV!$G$40,"furniture/equipment",Binning_WOE_IV!$G$41,"domestic appliance",Binning_WOE_IV!$G$41,"new car",Binning_WOE_IV!$G$42,"used car",Binning_WOE_IV!$G$43,"repairs",Binning_WOE_IV!$G$43,"business",Binning_WOE_IV!$G$44,"not found")} -> -0.47176157 | AB5: =_xlfn.LET(_xlpm.b,_xlfn.XLOOKUP(F5,Binning_WOE_IV!$AJ$2:$AJ$6,Binning_WOE_IV!$AK$2:$AK$6,"not found",0),IF(_xlpm.b="bin1",_xlfn.XLOOKUP(_xlpm.b,Binning_WOE_IV!$R$45:$R$48,Binning_WOE_IV!$G$45:$G$48,"not found",0),_xlfn.XLOOKUP(_xlpm.b,Binning_WOE_IV!$R$45:$R$48,Binning_WOE_IV!$G$45:$G$48,"not found",0))) -> -0.23980372 | AC5: =_xlfn.LET(_xlpm.b,_xlfn.XLOOKUP(G5,Binning_WOE_IV!$AL$2:$AL$6,Binning_WOE_IV!$AM$2:$AM$6,"not found",0),IF(_xlpm.b="bin1",_xlfn.XLOOKUP(_xlpm.b,Binning_WOE_IV!$R$49:$R$52,Binning_WOE_IV!$G$49:$G$52,"not found",0),_xlfn.XLOOKUP(_xlpm.b,Binning_WOE_IV!$R$49:$R$52,Binning_WOE_IV!$G$49:$G$52,"not found",0))) -> 0.3165647 | AD5: =_xlfn.XLOOKUP(_xlfn.XLOOKUP(I5,Binning_WOE_IV!$AN$2:$AN$5,Binning_WOE_IV!$AO$2:$AO$5,"not found",0),Binning_WOE_IV!$R$53:$R$55,Binning_WOE_IV!$G$53:$G$55,"not found",0) -> -0.20099342 | AE5: =_xlfn.LET(_xlpm.b,_xlfn.XLOOKUP(L5,Binning_WOE_IV!$AQ$2:$AQ$5,Binning_WOE_IV!$AR$2:$AR$5,"not found",0),IF(_xlpm.b="bin4",_xlfn.XLOOKUP(_xlpm.b,Binning_WOE_IV!$R$58:$R$61,Binning_WOE_IV!$G$58:$G$61,"not found",0),_xlfn.XLOOKUP(_xlpm.b,Binning_WOE_IV!$R$58:$R$61,Binning_WOE_IV!$G$58:$G$61,"not found",0))) -> -0.11389117 | AF5: =_xlfn.XLOOKUP(_xlfn.XLOOKUP(N5,Binning_WOE_IV!$AS$2:$AS$4,Binning_WOE_IV!$AT$2:$AT$4,"not found",0),Binning_WOE_IV!$R$62:$R$63,Binning_WOE_IV!$G$62:$G$63,"not found",0) -> 0.12957806 | AG5: =_xlfn.XLOOKUP(_xlfn.XLOOKUP(O5,Binning_WOE_IV!$AU$2:$AU$4,Binning_WOE_IV!$AV$2:$AV$4,"not found",0),Binning_WOE_IV!$R$64:$R$65,Binning_WOE_IV!$G$64:$G$65,"not found",0) -> -0.49192724 | AH5: =V5*TRAIN_SUMMARY!$C$3 -> 0.74681908 | AI5: =W5*TRAIN_SUMMARY!$C$4 -> 0.050912844 | AJ5: =X5*TRAIN_SUMMARY!$C$5 -> -0.17565257 | AK5: =Y5*TRAIN_SUMMARY!$C$6 -> 0.53190423 | AL5: =Z5*TRAIN_SUMMARY!$C$7 -> 0.68384 | AM5: =AA5*TRAIN_SUMMARY!$C$8 -> 0.48833778 | AN5: =AB5*TRAIN_SUMMARY!$C$9 -> 0.17108449 | AO5: =AC5*TRAIN_SUMMARY!$C$10 -> -0.18469041 | AP5: =AD5*TRAIN_SUMMARY!$C$11 -> 0.23813847 | AQ5: =AE5*TRAIN_SUMMARY!$C$12 -> 0.061778554 | AR5: =AF5*TRAIN_SUMMARY!$C$13 -> -0.079424742 | AS5: =AG5*TRAIN_SUMMARY!$C$14 -> 0.186008 | AT5: =TRAIN_SUMMARY!$C$2+SUM(AH5:AS5) -> 1.8976549 | AU5: =1/(1+EXP(-AT5)) -> 0.86962588 | AV5: =-((U5*LN(AU5))+(1-U5)*LN(1-AU5)) -> 0.13969219 | AW5: =IF(U5=0,1,0) -> 0 | AX5: =IF(U5=1,1,0) -> 1 | AY5: =AY4+AW5 -> 0 | AZ5: =AZ4+AX5 -> 4 | BA5: =AY5/SUM($AW$2:$AW$701) -> 0 | BB5: =AZ5/SUM($AX$2:$AX$701) -> 0.018604651 | BC5: =ABS(BA5-BB5) -> 0.018604651 | BD5: =BB5 -> 0.018604651 | BE5: =BA5 -> 0 | BF5: =VLOOKUP(AH5,POINTS_TABLE!$D$2:$E$6,2,FALSE) -> 32.322965 | BG5: =VLOOKUP(AI5,POINTS_TABLE!$D$7:$E$12,2,FALSE) -> 2.2035512 | BH5: =VLOOKUP(AJ5,POINTS_TABLE!$D$13:$E$18,2,FALSE) -> -7.6023925 | BI5: =VLOOKUP(AK5,POINTS_TABLE!$D$21:$E$24,2,FALSE) -> 23.021268 | BJ5: =VLOOKUP(AL5,POINTS_TABLE!$D$25:$E$27,2,FALSE) -> 29.597177 | BK5: =VLOOKUP(AM5,POINTS_TABLE!$D$28:$E$33,2,FALSE) -> 21.135675 | BL5: =VLOOKUP(AN5,POINTS_TABLE!$D$34:$E$37,2,FALSE) -> 7.4046822 | BM5: =VLOOKUP(AO5,POINTS_TABLE!$D$38:$E$41,2,FALSE) -> -7.9935582 | BN5: =VLOOKUP(AP5,POINTS_TABLE!$D$42:$E$44,2,FALSE) -> 10.306836 | BO5: =VLOOKUP(AQ5,POINTS_TABLE!$D$45:$E$48,2,FALSE) -> 2.6738284 | BP5: =VLOOKUP(AR5,POINTS_TABLE!$D$49:$E$50,2,FALSE) -> -3.4375704 | BQ5: =VLOOKUP(AS5,POINTS_TABLE!$D$51:$E$52,2,FALSE) -> 8.0505844 | BR5: =ROUND(SCORECARD_SCALLING!$C$6-SUM(BF5:BQ5)-TRAIN_SUMMARY!$C$2*SCORECARD_SCALLING!$C$5,0) -> 388 | BS5: =IF(BR5>=580,"Accept",IF(AND(BR5>=500,BR5<580),"Manual review","Reject")) -> Reject | BT5: =IF(BS5="Reject",1,IF(BS5="Manual review",2,3)) -> 1
A6: 0<=X<200 | B6: 48 | C6: all paid | D6: business | E6: 6416 | F6: <100 | G6: >=7 | H6: 4 | I6: female div/dep/mar | J6: none | K6: 3 | L6: no known property | M6: 59 | N6: none | O6: rent | P6: 1 | Q6: skilled | R6: 1 | S6: none | T6: yes | U6: 1 | V6: =_xlfn.XLOOKUP(B6,Binning_WOE_IV!$C$2:$C$6,Binning_WOE_IV!$I$2:$I$6,"not found",-1) -> -0.94704226 | W6: =_xlfn.XLOOKUP(E6,Binning_WOE_IV!$C$7:$C$12,Binning_WOE_IV!$I$7:$I$12,"not found",-1) -> -0.10201454 | X6: =_xlfn.XLOOKUP(M6,Binning_WOE_IV!$C$13:$C$18,Binning_WOE_IV!$I$13:$I$18,"not found",-1) -> 0.42044277 | Y6: =_xlfn.XLOOKUP(A6,Binning_WOE_IV!$B$32:$B$35,Binning_WOE_IV!$G$32:$G$35,"not found",0) -> -0.4555709 | Z6: =_xlfn.XLOOKUP(_xlfn.XLOOKUP(C6,Binning_WOE_IV!$AF$2:$AF$6,Binning_WOE_IV!$AG$2:$AG$6,"not found",0),Binning_WOE_IV!$R$36:$R$38,Binning_WOE_IV!$G$36:$G$38,"not found",0) -> -1.2442938 | AA6: {=_xlfn.SWITCH(D6,"radio/tv",Binning_WOE_IV!$G$39,"other",Binning_WOE_IV!$G$39,"education",Binning_WOE_IV!$G$40,"retraining",Binning_WOE_IV!$G$40,"furniture/equipment",Binning_WOE_IV!$G$41,"domestic appliance",Binning_WOE_IV!$G$41,"new car",Binning_WOE_IV!$G$42,"used car",Binning_WOE_IV!$G$43,"repairs",Binning_WOE_IV!$G$43,"business",Binning_WOE_IV!$G$44,"not found")} -> -0.47176157 | AB6: =_xlfn.LET(_xlpm.b,_xlfn.XLOOKUP(F6,Binning_WOE_IV!$AJ$2:$AJ$6,Binning_WOE_IV!$AK$2:$AK$6,"not found",0),IF(_xlpm.b="bin1",_xlfn.XLOOKUP(_xlpm.b,Binning_WOE_IV!$R$45:$R$48,Binning_WOE_IV!$G$45:$G$48,"not found",0),_xlfn.XLOOKUP(_xlpm.b,Binning_WOE_IV!$R$45:$R$48,Binning_WOE_IV!$G$45:$G$48,"not found",0))) -> -0.23980372 | AC6: =_xlfn.LET(_xlpm.b,_xlfn.XLOOKUP(G6,Binning_WOE_IV!$AL$2:$AL$6,Binning_WOE_IV!$AM$2:$AM$6,"not found",0),IF(_xlpm.b="bin1",_xlfn.XLOOKUP(_xlpm.b,Binning_WOE_IV!$R$49:$R$52,Binning_WOE_IV!$G$49:$G$52,"not found",0),_xlfn.XLOOKUP(_xlpm.b,Binning_WOE_IV!$R$49:$R$52,Binning_WOE_IV!$G$49:$G$52,"not found",0))) -> 0.3165647 | AD6: =_xlfn.XLOOKUP(_xlfn.XLOOKUP(I6,Binning_WOE_IV!$AN$2:$AN$5,Binning_WOE_IV!$AO$2:$AO$5,"not found",0),Binning_WOE_IV!$R$53:$R$55,Binning_WOE_IV!$G$53:$G$55,"not found",0) -> -0.20099342 | AE6: =_xlfn.LET(_xlpm.b,_xlfn.XLOOKUP(L6,Binning_WOE_IV!$AQ$2:$AQ$5,Binning_WOE_IV!$AR$2:$AR$5,"not found",0),IF(_xlpm.b="bin4",_xlfn.XLOOKUP(_xlpm.b,Binning_WOE_IV!$R$58:$R$61,Binning_WOE_IV!$G$58:$G$61,"not found",0),_xlfn.XLOOKUP(_xlpm.b,Binning_WOE_IV!$R$58:$R$61,Binning_WOE_IV!$G$58:$G$61,"not found",0))) -> -0.56219643 | AF6: =_xlfn.XLOOKUP(_xlfn.XLOOKUP(N6,Binning_WOE_IV!$AS$2:$AS$4,Binning_WOE_IV!$AT$2:$AT$4,"not found",0),Binning_WOE_IV!$R$62:$R$63,Binning_WOE_IV!$G$62:$G$63,"not found",0) -> 0.12957806 | AG6: =_xlfn.XLOOKUP(_xlfn.XLOOKUP(O6,Binning_WOE_IV!$AU$2:$AU$4,Binning_WOE_IV!$AV$2:$AV$4,"not found",0),Binning_WOE_IV!$R$64:$R$65,Binning_WOE_IV!$G$64:$G$65,"not found",0) -> -0.49192724 | AH6: =V6*TRAIN_SUMMARY!$C$3 -> 0.74681908 | AI6: =W6*TRAIN_SUMMARY!$C$4 -> 0.050912844 | AJ6: =X6*TRAIN_SUMMARY!$C$5 -> -0.26777415 | AK6: =Y6*TRAIN_SUMMARY!$C$6 -> 0.3570927 | AL6: =Z6*TRAIN_SUMMARY!$C$7 -> 0.68384 | AM6: =AA6*TRAIN_SUMMARY!$C$8 -> 0.48833778 | AN6: =AB6*TRAIN_SUMMARY!$C$9 -> 0.17108449 | AO6: =AC6*TRAIN_SUMMARY!$C$10 -> -0.18469041 | AP6: =AD6*TRAIN_SUMMARY!$C$11 -> 0.23813847 | AQ6: =AE6*TRAIN_SUMMARY!$C$12 -> 0.30495501 | AR6: =AF6*TRAIN_SUMMARY!$C$13 -> -0.079424742 | AS6: =AG6*TRAIN_SUMMARY!$C$14 -> 0.186008 | AT6: =TRAIN_SUMMARY!$C$2+SUM(AH6:AS6) -> 1.8738983 | AU6: =1/(1+EXP(-AT6)) -> 0.86690869 | AV6: =-((U6*LN(AU6))+(1-U6)*LN(1-AU6)) -> 0.14282162 | AW6: =IF(U6=0,1,0) -> 0 | AX6: =IF(U6=1,1,0) -> 1 | AY6: =AY5+AW6 -> 0 | AZ6: =AZ5+AX6 -> 5 | BA6: =AY6/SUM($AW$2:$AW$701) -> 0 | BB6: =AZ6/SUM($AX$2:$AX$701) -> 0.023255814 | BC6: =ABS(BA6-BB6) -> 0.023255814 | BD6: =BB6 -> 0.023255814 | BE6: =BA6 -> 0 | BF6: =VLOOKUP(AH6,POINTS_TABLE!$D$2:$E$6,2,FALSE) -> 32.322965 | BG6: =VLOOKUP(AI6,POINTS_TABLE!$D$7:$E$12,2,FALSE) -> 2.2035512 | BH6: =VLOOKUP(AJ6,POINTS_TABLE!$D$13:$E$18,2,FALSE) -> -11.589493 | BI6: =VLOOKUP(AK6,POINTS_TABLE!$D$21:$E$24,2,FALSE) -> 15.455276 | BJ6: =VLOOKUP(AL6,POINTS_TABLE!$D$25:$E$27,2,FALSE) -> 29.597177 | BK6: =VLOOKUP(AM6,POINTS_TABLE!$D$28:$E$33,2,FALSE) -> 21.135675 | BL6: =VLOOKUP(AN6,POINTS_TABLE!$D$34:$E$37,2,FALSE) -> 7.4046822 | BM6: =VLOOKUP(AO6,POINTS_TABLE!$D$38:$E$41,2,FALSE) -> -7.9935582 | BN6: =VLOOKUP(AP6,POINTS_TABLE!$D$42:$E$44,2,FALSE) -> 10.306836 | BO6: =VLOOKUP(AQ6,POINTS_TABLE!$D$45:$E$48,2,FALSE) -> 13.198713 | BP6: =VLOOKUP(AR6,POINTS_TABLE!$D$49:$E$50,2,FALSE) -> -3.4375704 | BQ6: =VLOOKUP(AS6,POINTS_TABLE!$D$51:$E$52,2,FALSE) -> 8.0505844 | BR6: =ROUND(SCORECARD_SCALLING!$C$6-SUM(BF6:BQ6)-TRAIN_SUMMARY!$C$2*SCORECARD_SCALLING!$C$5,0) -> 389 | BS6: =IF(BR6>=580,"Accept",IF(AND(BR6>=500,BR6<580),"Manual review","Reject")) -> Reject | BT6: =IF(BS6="Reject",1,IF(BS6="Manual review",2,3)) -> 1
A7: 0<=X<200 | B7: 48 | C7: no credits/all paid | D7: new car | E7: 8358 | F7: 500<=X<1000 | G7: <1 | H7: 1 | I7: female div/dep/mar | J7: none | K7: 1 | L7: car | M7: 30 | N7: none | O7: own | P7: 2 | Q7: skilled | R7: 1 | S7: none | T7: yes | U7: 0 | V7: =_xlfn.XLOOKUP(B7,Binning_WOE_IV!$C$2:$C$6,Binning_WOE_IV!$I$2:$I$6,"not found",-1) -> -0.94704226 | W7: =_xlfn.XLOOKUP(E7,Binning_WOE_IV!$C$7:$C$12,Binning_WOE_IV!$I$7:$I$12,"not found",-1) -> -0.98786425 | X7: =_xlfn.XLOOKUP(M7,Binning_WOE_IV!$C$13:$C$18,Binning_WOE_IV!$I$13:$I$18,"not found",-1) -> -0.090210644 | Y7: =_xlfn.XLOOKUP(A7,Binning_WOE_IV!$B$32:$B$35,Binning_WOE_IV!$G$32:$G$35,"not found",0) -> -0.4555709 | Z7: =_xlfn.XLOOKUP(_xlfn.XLOOKUP(C7,Binning_WOE_IV!$AF$2:$AF$6,Binning_WOE_IV!$AG$2:$AG$6,"not found",0),Binning_WOE_IV!$R$36:$R$38,Binning_WOE_IV!$G$36:$G$38,"not found",0) -> -1.2442938 | AA7: {=_xlfn.SWITCH(D7,"radio/tv",Binning_WOE_IV!$G$39,"other",Binning_WOE_IV!$G$39,"education",Binning_WOE_IV!$G$40,"retraining",Binning_WOE_IV!$G$40,"furniture/equipment",Binning_WOE_IV!$G$41,"domestic appliance",Binning_WOE_IV!$G$41,"new car",Binning_WOE_IV!$G$42,"used car",Binning_WOE_IV!$G$43,"repairs",Binning_WOE_IV!$G$43,"business",Binning_WOE_IV!$G$44,"not found")} -> -0.37050784 | AB7: =_xlfn.LET(_xlpm.b,_xlfn.XLOOKUP(F7,Binning_WOE_IV!$AJ$2:$AJ$6,Binning_WOE_IV!$AK$2:$AK$6,"not found",0),IF(_xlpm.b="bin1",_xlfn.XLOOKUP(_xlpm.b,Binning_WOE_IV!$R$45:$R$48,Binning_WOE_IV!$G$45:$G$48,"not found",0),_xlfn.XLOOKUP(_xlpm.b,Binning_WOE_IV!$R$45:$R$48,Binning_WOE_IV!$G$45:$G$48,"not found",0))) -> 0.69794664 | AC7: =_xlfn.LET(_xlpm.b,_xlfn.XLOOKUP(G7,Binning_WOE_IV!$AL$2:$AL$6,Binning_WOE_IV!$AM$2:$AM$6,"not found",0),IF(_xlpm.b="bin1",_xlfn.XLOOKUP(_xlpm.b,Binning_WOE_IV!$R$49:$R$52,Binning_WOE_IV!$G$49:$G$52,"not found",0),_xlfn.XLOOKUP(_xlpm.b,Binning_WOE_IV!$R$49:$R$52,Binning_WOE_IV!$G$49:$G$52,"not found",0))) -> -0.49142736 | AD7: =_xlfn.XLOOKUP(_xlfn.XLOOKUP(I7,Binning_WOE_IV!$AN$2:$AN$5,Binning_WOE_IV!$AO$2:$AO$5,"not found",0),Binning_WOE_IV!$R$53:$R$55,Binning_WOE_IV!$G$53:$G$55,"not found",0) -> -0.20099342 | AE7: =_xlfn.LET(_xlpm.b,_xlfn.XLOOKUP(L7,Binning_WOE_IV!$AQ$2:$AQ$5,Binning_WOE_IV!$AR$2:$AR$5,"not found",0),IF(_xlpm.b="bin4",_xlfn.XLOOKUP(_xlpm.b,Binning_WOE_IV!$R$58:$R$61,Binning_WOE_IV!$G$58:$G$61,"not found",0),_xlfn.XLOOKUP(_xlpm.b,Binning_WOE_IV!$R$58:$R$61,Binning_WOE_IV!$G$58:$G$61,"not found",0))) -> -0.11389117 | AF7: =_xlfn.XLOOKUP(_xlfn.XLOOKUP(N7,Binning_WOE_IV!$AS$2:$AS$4,Binning_WOE_IV!$AT$2:$AT$4,"not found",0),Binning_WOE_IV!$R$62:$R$63,Binning_WOE_IV!$G$62:$G$63,"not found",0) -> 0.12957806 | AG7: =_xlfn.XLOOKUP(_xlfn.XLOOKUP(O7,Binning_WOE_IV!$AU$2:$AU$4,Binning_WOE_IV!$AV$2:$AV$4,"not found",0),Binning_WOE_IV!$R$64:$R$65,Binning_WOE_IV!$G$64:$G$65,"not found",0) -> 0.23435623 | AH7: =V7*TRAIN_SUMMARY!$C$3 -> 0.74681908 | AI7: =W7*TRAIN_SUMMARY!$C$4 -> 0.49301773 | AJ7: =X7*TRAIN_SUMMARY!$C$5 -> 0.057453904 | AK7: =Y7*TRAIN_SUMMARY!$C$6 -> 0.3570927 | AL7: =Z7*TRAIN_SUMMARY!$C$7 -> 0.68384 | AM7: =AA7*TRAIN_SUMMARY!$C$8 -> 0.38352631 | AN7: =AB7*TRAIN_SUMMARY!$C$9 -> -0.49793991 | AO7: =AC7*TRAIN_SUMMARY!$C$10 -> 0.28670892 | AP7: =AD7*TRAIN_SUMMARY!$C$11 -> 0.23813847 | AQ7: =AE7*TRAIN_SUMMARY!$C$12 -> 0.061778554 | AR7: =AF7*TRAIN_SUMMARY!$C$13 -> -0.079424742 | AS7: =AG7*TRAIN_SUMMARY!$C$14 -> -0.088615 | AT7: =TRAIN_SUMMARY!$C$2+SUM(AH7:AS7) -> 1.8209952 | AU7: =1/(1+EXP(-AT7)) -> 0.8606855 | AV7: =-((U7*LN(AU7))+(1-U7)*LN(1-AU7)) -> 1.9710213 | AW7: =IF(U7=0,1,0) -> 1 | AX7: =IF(U7=1,1,0) -> 0 | AY7: =AY6+AW7 -> 1 | AZ7: =AZ6+AX7 -> 5 | BA7: =AY7/SUM($AW$2:$AW$701) -> 0.0020618557 | BB7: =AZ7/SUM($AX$2:$AX$701) -> 0.023255814 | BC7: =ABS(BA7-BB7) -> 0.021193958 | BD7: =BB7 -> 0.023255814 | BE7: =BA7 -> 0.0020618557 | BF7: =VLOOKUP(AH7,POINTS_TABLE!$D$2:$E$6,2,FALSE) -> 32.322965 | BG7: =VLOOKUP(AI7,POINTS_TABLE!$D$7:$E$12,2,FALSE) -> 21.338227 | BH7: =VLOOKUP(AJ7,POINTS_TABLE!$D$13:$E$18,2,FALSE) -> 2.4866539 | BI7: =VLOOKUP(AK7,POINTS_TABLE!$D$21:$E$24,2,FALSE) -> 15.455276 | BJ7: =VLOOKUP(AL7,POINTS_TABLE!$D$25:$E$27,2,FALSE) -> 29.597177 | BK7: =VLOOKUP(AM7,POINTS_TABLE!$D$28:$E$33,2,FALSE) -> 16.599345 | BL7: =VLOOKUP(AN7,POINTS_TABLE!$D$34:$E$37,2,FALSE) -> -21.551263 | BM7: =VLOOKUP(AO7,POINTS_TABLE!$D$38:$E$41,2,FALSE) -> 12.409006 | BN7: =VLOOKUP(AP7,POINTS_TABLE!$D$42:$E$44,2,FALSE) -> 10.306836 | BO7: =VLOOKUP(AQ7,POINTS_TABLE!$D$45:$E$48,2,FALSE) -> 2.6738284 | BP7: =VLOOKUP(AR7,POINTS_TABLE!$D$49:$E$50,2,FALSE) -> -3.4375704 | BQ7: =VLOOKUP(AS7,POINTS_TABLE!$D$51:$E$52,2,FALSE) -> -3.8353326 | BR7: =ROUND(SCORECARD_SCALLING!$C$6-SUM(BF7:BQ7)-TRAIN_SUMMARY!$C$2*SCORECARD_SCALLING!$C$5,0) -> 392 | BS7: =IF(BR7>=580,"Accept",IF(AND(BR7>=500,BR7<580),"Manual review","Reject")) -> Reject | BT7: =IF(BS7="Reject",1,IF(BS7="Manual review",2,3)) -> 1
A8: <0 | B8: 24 | C8: all paid | D8: new car | E8: 1193 | F8: <100 | G8: unemployed | H8: 1 | I8: female div/dep/mar | J8: co applicant | K8: 4 | L8: no known property | M8: 29 | N8: none | O8: rent | P8: 2 | Q8: unemp/unskilled non res | R8: 1 | S8: none | T8: yes | U8: 1 | V8: =_xlfn.XLOOKUP(B8,Binning_WOE_IV!$C$2:$C$6,Binning_WOE_IV!$I$2:$I$6,"not found",-1) -> -0.12917431 | W8: =_xlfn.XLOOKUP(E8,Binning_WOE_IV!$C$7:$C$12,Binning_WOE_IV!$I$7:$I$12,"not found",-1) -> 0.16104878 | X8: =_xlfn.XLOOKUP(M8,Binning_WOE_IV!$C$13:$C$18,Binning_WOE_IV!$I$13:$I$18,"not found",-1) -> -0.13233987 | Y8: =_xlfn.XLOOKUP(A8,Binning_WOE_IV!$B$32:$B$35,Binning_WOE_IV!$G$32:$G$35,"not found",0) -> -0.67859154 | Z8: =_xlfn.XLOOKUP(_xlfn.XLOOKUP(C8,Binning_WOE_IV!$AF$2:$AF$6,Binning_WOE_IV!$AG$2:$AG$6,"not found",0),Binning_WOE_IV!$R$36:$R$38,Binning_WOE_IV!$G$36:$G$38,"not found",0) -> -1.2442938 | AA8: {=_xlfn.SWITCH(D8,"radio/tv",Binning_WOE_IV!$G$39,"other",Binning_WOE_IV!$G$39,"education",Binning_WOE_IV!$G$40,"retraining",Binning_WOE_IV!$G$40,"furniture/equipment",Binning_WOE_IV!$G$41,"domestic appliance",Binning_WOE_IV!$G$41,"new car",Binning_WOE_IV!$G$42,"used car",Binning_WOE_IV!$G$43,"repairs",Binning_WOE_IV!$G$43,"business",Binning_WOE_IV!$G$44,"not found")} -> -0.37050784 | AB8: =_xlfn.LET(_xlpm.b,_xlfn.XLOOKUP(F8,Binning_WOE_IV!$AJ$2:$AJ$6,Binning_WOE_IV!$AK$2:$AK$6,"not found",0),IF(_xlpm.b="bin1",_xlfn.XLOOKUP(_xlpm.b,Binning_WOE_IV!$R$45:$R$48,Binning_WOE_IV!$G$45:$G$48,"not found",0),_xlfn.XLOOKUP(_xlpm.b,Binning_WOE_IV!$R$45:$R$48,Binning_WOE_IV!$G$45:$G$48,"not found",0))) -> -0.23980372 | AC8: =_xlfn.LET(_xlpm.b,_xlfn.XLOOKUP(G8,Binning_WOE_IV!$AL$2:$AL$6,Binning_WOE_IV!$AM$2:$AM$6,"not found",0),IF(_xlpm.b="bin1",_xlfn.XLOOKUP(_xlpm.b,Binning_WOE_IV!$R$49:$R$52,Binning_WOE_IV!$G$49:$G$52,"not found",0),_xlfn.XLOOKUP(_xlpm.b,Binning_WOE_IV!$R$49:$R$52,Binning_WOE_IV!$G$49:$G$52,"not found",0))) -> -0.12036368 | AD8: =_xlfn.XLOOKUP(_xlfn.XLOOKUP(I8,Binning_WOE_IV!$AN$2:$AN$5,Binning_WOE_IV!$AO$2:$AO$5,"not found",0),Binning_WOE_IV!$R$53:$R$55,Binning_WOE_IV!$G$53:$G$55,"not found",0) -> -0.20099342 | AE8: =_xlfn.LET(_xlpm.b,_xlfn.XLOOKUP(L8,Binning_WOE_IV!$AQ$2:$AQ$5,Binning_WOE_IV!$AR$2:$AR$5,"not found",0),IF(_xlpm.b="bin4",_xlfn.XLOOKUP(_xlpm.b,Binning_WOE_IV!$R$58:$R$61,Binning_WOE_IV!$G$58:$G$61,"not found",0),_xlfn.XLOOKUP(_xlpm.b,Binning_WOE_IV!$R$58:$R$61,Binning_WOE_IV!$G$58:$G$61,"not found",0))) -> -0.56219643 | AF8: =_xlfn.XLOOKUP(_xlfn.XLOOKUP(N8,Binning_WOE_IV!$AS$2:$AS$4,Binning_WOE_IV!$AT$2:$AT$4,"not found",0),Binning_WOE_IV!$R$62:$R$63,Binning_WOE_IV!$G$62:$G$63,"not found",0) -> 0.12957806 | AG8: =_xlfn.XLOOKUP(_xlfn.XLOOKUP(O8,Binning_WOE_IV!$AU$2:$AU$4,Binning_WOE_IV!$AV$2:$AV$4,"not found",0),Binning_WOE_IV!$R$64:$R$65,Binning_WOE_IV!$G$64:$G$65,"not found",0) -> -0.49192724 | AH8: =V8*TRAIN_SUMMARY!$C$3 -> 0.10186435 | AI8: =W8*TRAIN_SUMMARY!$C$4 -> -0.080375317 | AJ8: =X8*TRAIN_SUMMARY!$C$5 -> 0.084285423 | AK8: =Y8*TRAIN_SUMMARY!$C$6 -> 0.53190423 | AL8: =Z8*TRAIN_SUMMARY!$C$7 -> 0.68384 | AM8: =AA8*TRAIN_SUMMARY!$C$8 -> 0.38352631 | AN8: =AB8*TRAIN_SUMMARY!$C$9 -> 0.17108449 | AO8: =AC8*TRAIN_SUMMARY!$C$10 -> 0.07022267 | AP8: =AD8*TRAIN_SUMMARY!$C$11 -> 0.23813847 | AQ8: =AE8*TRAIN_SUMMARY!$C$12 -> 0.30495501 | AR8: =AF8*TRAIN_SUMMARY!$C$13 -> -0.079424742 | AS8: =AG8*TRAIN_SUMMARY!$C$14 -> 0.186008 | AT8: =TRAIN_SUMMARY!$C$2+SUM(AH8:AS8) -> 1.7746281 | AU8: =1/(1+EXP(-AT8)) -> 0.85503227 | AV8: =-((U8*LN(AU8))+(1-U8)*LN(1-AU8)) -> 0.15661606 | AW8: =IF(U8=0,1,0) -> 0 | AX8: =IF(U8=1,1,0) -> 1 | AY8: =AY7+AW8 -> 1 | AZ8: =AZ7+AX8 -> 6 | BA8: =AY8/SUM($AW$2:$AW$701) -> 0.0020618557 | BB8: =AZ8/SUM($AX$2:$AX$701) -> 0.027906977 | BC8: =ABS(BA8-BB8) -> 0.025845121 | BD8: =BB8 -> 0.027906977 | BE8: =BA8 -> 0.0020618557 | BF8: =VLOOKUP(AH8,POINTS_TABLE!$D$2:$E$6,2,FALSE) -> 4.4087756 | BG8: =VLOOKUP(AI8,POINTS_TABLE!$D$7:$E$12,2,FALSE) -> -3.4787121 | BH8: =VLOOKUP(AJ8,POINTS_TABLE!$D$13:$E$18,2,FALSE) -> 3.6479449 | BI8: =VLOOKUP(AK8,POINTS_TABLE!$D$21:$E$24,2,FALSE) -> 23.021268 | BJ8: =VLOOKUP(AL8,POINTS_TABLE!$D$25:$E$27,2,FALSE) -> 29.597177 | BK8: =VLOOKUP(AM8,POINTS_TABLE!$D$28:$E$33,2,FALSE) -> 16.599345 | BL8: =VLOOKUP(AN8,POINTS_TABLE!$D$34:$E$37,2,FALSE) -> 7.4046822 | BM8: =VLOOKUP(AO8,POINTS_TABLE!$D$38:$E$41,2,FALSE) -> 3.0392969 | BN8: =VLOOKUP(AP8,POINTS_TABLE!$D$42:$E$44,2,FALSE) -> 10.306836 | BO8: =VLOOKUP(AQ8,POINTS_TABLE!$D$45:$E$48,2,FALSE) -> 13.198713 | BP8: =VLOOKUP(AR8,POINTS_TABLE!$D$49:$E$50,2,FALSE) -> -3.4375704 | BQ8: =VLOOKUP(AS8,POINTS_TABLE!$D$51:$E$52,2,FALSE) -> 8.0505844 | BR8: =ROUND(SCORECARD_SCALLING!$C$6-SUM(BF8:BQ8)-TRAIN_SUMMARY!$C$2*SCORECARD_SCALLING!$C$5,0) -> 394 | BS8: =IF(BR8>=580,"Accept",IF(AND(BR8>=500,BR8<580),"Manual review","Reject")) -> Reject | BT8: =IF(BS8="Reject",1,IF(BS8="Manual review",2,3)) -> 1
